[2024-02-21T10:34:13.985+0000] {taskinstance.py:1956} INFO - Dependencies all met for dep_context=non-requeueable deps ti=<TaskInstance: airflow-s3-mlflow.model_training manual__2024-02-21T10:33:51.308376+00:00 [queued]>
[2024-02-21T10:34:13.995+0000] {taskinstance.py:1956} INFO - Dependencies all met for dep_context=requeueable deps ti=<TaskInstance: airflow-s3-mlflow.model_training manual__2024-02-21T10:33:51.308376+00:00 [queued]>
[2024-02-21T10:34:13.996+0000] {taskinstance.py:2170} INFO - Starting attempt 1 of 1
[2024-02-21T10:34:14.018+0000] {taskinstance.py:2191} INFO - Executing <Task(PythonOperator): model_training> on 2024-02-21 10:33:51.308376+00:00
[2024-02-21T10:34:14.027+0000] {standard_task_runner.py:60} INFO - Started process 3102 to run task
[2024-02-21T10:34:14.030+0000] {standard_task_runner.py:87} INFO - Running: ['***', 'tasks', 'run', '***-s3-mlflow', 'model_training', 'manual__2024-02-21T10:33:51.308376+00:00', '--job-id', '117', '--raw', '--subdir', 'DAGS_FOLDER/***-aws-mlflow.py', '--cfg-path', '/tmp/tmphskv2cgb']
[2024-02-21T10:34:14.033+0000] {standard_task_runner.py:88} INFO - Job 117: Subtask model_training
[2024-02-21T10:34:14.053+0000] {logging_mixin.py:188} WARNING - /home/***/.local/lib/python3.8/site-packages/***/settings.py:194 DeprecationWarning: The sql_alchemy_conn option in [core] has been moved to the sql_alchemy_conn option in [database] - the old setting has been used, but please update your config.
[2024-02-21T10:34:14.089+0000] {task_command.py:423} INFO - Running <TaskInstance: airflow-s3-mlflow.model_training manual__2024-02-21T10:33:51.308376+00:00 [running]> on host b14d6cdb7c29
[2024-02-21T10:34:14.163+0000] {taskinstance.py:2480} INFO - Exporting env vars: AIRFLOW_CTX_DAG_OWNER='***' AIRFLOW_CTX_DAG_ID='***-s3-mlflow' AIRFLOW_CTX_TASK_ID='model_training' AIRFLOW_CTX_EXECUTION_DATE='2024-02-21T10:33:51.308376+00:00' AIRFLOW_CTX_TRY_NUMBER='1' AIRFLOW_CTX_DAG_RUN_ID='manual__2024-02-21T10:33:51.308376+00:00'
[2024-02-21T10:34:14.182+0000] {credentials.py:1147} INFO - Found credentials in environment variables.
[2024-02-21T10:34:17.077+0000] {logging_mixin.py:188} INFO - data file imported from s3
[2024-02-21T10:34:17.080+0000] {logging_mixin.py:188} INFO - data imported from s3
[2024-02-21T10:34:17.089+0000] {taskinstance.py:2698} ERROR - Task failed with exception
Traceback (most recent call last):
  File "/home/airflow/.local/lib/python3.8/site-packages/airflow/models/taskinstance.py", line 433, in _execute_task
    result = execute_callable(context=context, **execute_callable_kwargs)
  File "/home/airflow/.local/lib/python3.8/site-packages/airflow/operators/python.py", line 199, in execute
    return_value = self.execute_callable()
  File "/home/airflow/.local/lib/python3.8/site-packages/airflow/operators/python.py", line 216, in execute_callable
    return self.python_callable(*self.op_args, **self.op_kwargs)
  File "/opt/airflow/src/Modeltrainig/trainmodel.py", line 70, in mlflow_track
    alpha = args.alpha
NameError: name 'args' is not defined
[2024-02-21T10:34:17.108+0000] {taskinstance.py:1138} INFO - Marking task as FAILED. dag_id=***-s3-mlflow, task_id=model_training, execution_date=20240221T103351, start_date=20240221T103413, end_date=20240221T103417
[2024-02-21T10:34:17.124+0000] {standard_task_runner.py:107} ERROR - Failed to execute job 117 for task model_training (name 'args' is not defined; 3102)
[2024-02-21T10:34:17.146+0000] {local_task_job_runner.py:234} INFO - Task exited with return code 1
[2024-02-21T10:34:17.174+0000] {taskinstance.py:3280} INFO - 0 downstream tasks scheduled from follow-on schedule check
