[2024-02-21T10:35:03.445+0000] {taskinstance.py:1956} INFO - Dependencies all met for dep_context=non-requeueable deps ti=<TaskInstance: airflow-s3-mlflow.model_training manual__2024-02-21T10:34:42.528104+00:00 [queued]>
[2024-02-21T10:35:03.455+0000] {taskinstance.py:1956} INFO - Dependencies all met for dep_context=requeueable deps ti=<TaskInstance: airflow-s3-mlflow.model_training manual__2024-02-21T10:34:42.528104+00:00 [queued]>
[2024-02-21T10:35:03.456+0000] {taskinstance.py:2170} INFO - Starting attempt 1 of 1
[2024-02-21T10:35:03.472+0000] {taskinstance.py:2191} INFO - Executing <Task(PythonOperator): model_training> on 2024-02-21 10:34:42.528104+00:00
[2024-02-21T10:35:03.479+0000] {standard_task_runner.py:60} INFO - Started process 3261 to run task
[2024-02-21T10:35:03.481+0000] {standard_task_runner.py:87} INFO - Running: ['***', 'tasks', 'run', '***-s3-mlflow', 'model_training', 'manual__2024-02-21T10:34:42.528104+00:00', '--job-id', '125', '--raw', '--subdir', 'DAGS_FOLDER/***-aws-mlflow.py', '--cfg-path', '/tmp/tmp4hc4r3bh']
[2024-02-21T10:35:03.484+0000] {standard_task_runner.py:88} INFO - Job 125: Subtask model_training
[2024-02-21T10:35:03.502+0000] {logging_mixin.py:188} WARNING - /home/***/.local/lib/python3.8/site-packages/***/settings.py:194 DeprecationWarning: The sql_alchemy_conn option in [core] has been moved to the sql_alchemy_conn option in [database] - the old setting has been used, but please update your config.
[2024-02-21T10:35:03.536+0000] {task_command.py:423} INFO - Running <TaskInstance: airflow-s3-mlflow.model_training manual__2024-02-21T10:34:42.528104+00:00 [running]> on host b14d6cdb7c29
[2024-02-21T10:35:03.616+0000] {taskinstance.py:2480} INFO - Exporting env vars: AIRFLOW_CTX_DAG_OWNER='***' AIRFLOW_CTX_DAG_ID='***-s3-mlflow' AIRFLOW_CTX_TASK_ID='model_training' AIRFLOW_CTX_EXECUTION_DATE='2024-02-21T10:34:42.528104+00:00' AIRFLOW_CTX_TRY_NUMBER='1' AIRFLOW_CTX_DAG_RUN_ID='manual__2024-02-21T10:34:42.528104+00:00'
[2024-02-21T10:35:03.634+0000] {credentials.py:1147} INFO - Found credentials in environment variables.
[2024-02-21T10:35:06.643+0000] {logging_mixin.py:188} INFO - data file imported from s3
[2024-02-21T10:35:06.646+0000] {logging_mixin.py:188} INFO - data imported from s3
[2024-02-21T10:35:06.655+0000] {taskinstance.py:2698} ERROR - Task failed with exception
Traceback (most recent call last):
  File "/home/airflow/.local/lib/python3.8/site-packages/airflow/models/taskinstance.py", line 433, in _execute_task
    result = execute_callable(context=context, **execute_callable_kwargs)
  File "/home/airflow/.local/lib/python3.8/site-packages/airflow/operators/python.py", line 199, in execute
    return_value = self.execute_callable()
  File "/home/airflow/.local/lib/python3.8/site-packages/airflow/operators/python.py", line 216, in execute_callable
    return self.python_callable(*self.op_args, **self.op_kwargs)
  File "/opt/airflow/src/Modeltrainig/trainmodel.py", line 70, in mlflow_track
    alpha = args.alpha
NameError: name 'args' is not defined
[2024-02-21T10:35:06.686+0000] {taskinstance.py:1138} INFO - Marking task as FAILED. dag_id=***-s3-mlflow, task_id=model_training, execution_date=20240221T103442, start_date=20240221T103503, end_date=20240221T103506
[2024-02-21T10:35:06.704+0000] {standard_task_runner.py:107} ERROR - Failed to execute job 125 for task model_training (name 'args' is not defined; 3261)
[2024-02-21T10:35:06.720+0000] {local_task_job_runner.py:234} INFO - Task exited with return code 1
[2024-02-21T10:35:06.747+0000] {taskinstance.py:3280} INFO - 0 downstream tasks scheduled from follow-on schedule check
