[2024-02-20T10:19:08.365+0000] {taskinstance.py:1956} INFO - Dependencies all met for dep_context=non-requeueable deps ti=<TaskInstance: airflow-s3-mlflow.upload_to_s3 manual__2024-02-20T10:18:47.410301+00:00 [queued]>
[2024-02-20T10:19:08.376+0000] {taskinstance.py:1956} INFO - Dependencies all met for dep_context=requeueable deps ti=<TaskInstance: airflow-s3-mlflow.upload_to_s3 manual__2024-02-20T10:18:47.410301+00:00 [queued]>
[2024-02-20T10:19:08.377+0000] {taskinstance.py:2170} INFO - Starting attempt 1 of 1
[2024-02-20T10:19:08.393+0000] {taskinstance.py:2191} INFO - Executing <Task(PythonOperator): upload_to_s3> on 2024-02-20 10:18:47.410301+00:00
[2024-02-20T10:19:08.456+0000] {standard_task_runner.py:60} INFO - Started process 3766 to run task
[2024-02-20T10:19:08.461+0000] {standard_task_runner.py:87} INFO - Running: ['***', 'tasks', 'run', '***-s3-mlflow', 'upload_to_s3', 'manual__2024-02-20T10:18:47.410301+00:00', '--job-id', '33', '--raw', '--subdir', 'DAGS_FOLDER/***-aws-mlflow.py', '--cfg-path', '/tmp/tmpq33xpgk0']
[2024-02-20T10:19:08.465+0000] {standard_task_runner.py:88} INFO - Job 33: Subtask upload_to_s3
[2024-02-20T10:19:08.483+0000] {logging_mixin.py:188} WARNING - /home/***/.local/lib/python3.8/site-packages/***/settings.py:194 DeprecationWarning: The sql_alchemy_conn option in [core] has been moved to the sql_alchemy_conn option in [database] - the old setting has been used, but please update your config.
[2024-02-20T10:19:08.523+0000] {task_command.py:423} INFO - Running <TaskInstance: airflow-s3-mlflow.upload_to_s3 manual__2024-02-20T10:18:47.410301+00:00 [running]> on host 0980836b8fdf
[2024-02-20T10:19:08.622+0000] {taskinstance.py:2480} INFO - Exporting env vars: AIRFLOW_CTX_DAG_OWNER='***' AIRFLOW_CTX_DAG_ID='***-s3-mlflow' AIRFLOW_CTX_TASK_ID='upload_to_s3' AIRFLOW_CTX_EXECUTION_DATE='2024-02-20T10:18:47.410301+00:00' AIRFLOW_CTX_TRY_NUMBER='1' AIRFLOW_CTX_DAG_RUN_ID='manual__2024-02-20T10:18:47.410301+00:00'
[2024-02-20T10:19:08.930+0000] {taskinstance.py:2698} ERROR - Task failed with exception
Traceback (most recent call last):
  File "/home/airflow/.local/lib/python3.8/site-packages/airflow/models/taskinstance.py", line 433, in _execute_task
    result = execute_callable(context=context, **execute_callable_kwargs)
  File "/home/airflow/.local/lib/python3.8/site-packages/airflow/operators/python.py", line 199, in execute
    return_value = self.execute_callable()
  File "/home/airflow/.local/lib/python3.8/site-packages/airflow/operators/python.py", line 216, in execute_callable
    return self.python_callable(*self.op_args, **self.op_kwargs)
  File "/opt/airflow/src/preprocessing/uploaddata.py", line 14, in upload_to_s3
    s3_hook.load_string(
  File "/home/airflow/.local/lib/python3.8/site-packages/airflow/providers/amazon/aws/hooks/s3.py", line 122, in wrapper
    bound_args = function_signature.bind(*args, **kwargs)
  File "/usr/local/lib/python3.8/inspect.py", line 3037, in bind
    return self._bind(args, kwargs)
  File "/usr/local/lib/python3.8/inspect.py", line 2952, in _bind
    raise TypeError(msg) from None
TypeError: missing a required argument: 'string_data'
[2024-02-20T10:19:08.956+0000] {taskinstance.py:1138} INFO - Marking task as FAILED. dag_id=***-s3-mlflow, task_id=upload_to_s3, execution_date=20240220T101847, start_date=20240220T101908, end_date=20240220T101908
[2024-02-20T10:19:08.974+0000] {standard_task_runner.py:107} ERROR - Failed to execute job 33 for task upload_to_s3 (missing a required argument: 'string_data'; 3766)
[2024-02-20T10:19:08.996+0000] {local_task_job_runner.py:234} INFO - Task exited with return code 1
[2024-02-20T10:19:09.023+0000] {taskinstance.py:3280} INFO - 0 downstream tasks scheduled from follow-on schedule check
