[2024-02-21T10:15:23.695+0000] {taskinstance.py:1956} INFO - Dependencies all met for dep_context=non-requeueable deps ti=<TaskInstance: airflow-s3-mlflow.model_training manual__2024-02-21T10:15:00.704998+00:00 [queued]>
[2024-02-21T10:15:23.705+0000] {taskinstance.py:1956} INFO - Dependencies all met for dep_context=requeueable deps ti=<TaskInstance: airflow-s3-mlflow.model_training manual__2024-02-21T10:15:00.704998+00:00 [queued]>
[2024-02-21T10:15:23.706+0000] {taskinstance.py:2170} INFO - Starting attempt 1 of 1
[2024-02-21T10:15:23.720+0000] {taskinstance.py:2191} INFO - Executing <Task(PythonOperator): model_training> on 2024-02-21 10:15:00.704998+00:00
[2024-02-21T10:15:23.729+0000] {standard_task_runner.py:60} INFO - Started process 957 to run task
[2024-02-21T10:15:23.732+0000] {standard_task_runner.py:87} INFO - Running: ['***', 'tasks', 'run', '***-s3-mlflow', 'model_training', 'manual__2024-02-21T10:15:00.704998+00:00', '--job-id', '53', '--raw', '--subdir', 'DAGS_FOLDER/***-aws-mlflow.py', '--cfg-path', '/tmp/tmpyrzgnqct']
[2024-02-21T10:15:23.734+0000] {standard_task_runner.py:88} INFO - Job 53: Subtask model_training
[2024-02-21T10:15:23.752+0000] {logging_mixin.py:188} WARNING - /home/***/.local/lib/python3.8/site-packages/***/settings.py:194 DeprecationWarning: The sql_alchemy_conn option in [core] has been moved to the sql_alchemy_conn option in [database] - the old setting has been used, but please update your config.
[2024-02-21T10:15:23.787+0000] {task_command.py:423} INFO - Running <TaskInstance: airflow-s3-mlflow.model_training manual__2024-02-21T10:15:00.704998+00:00 [running]> on host b14d6cdb7c29
[2024-02-21T10:15:23.862+0000] {taskinstance.py:2480} INFO - Exporting env vars: AIRFLOW_CTX_DAG_OWNER='***' AIRFLOW_CTX_DAG_ID='***-s3-mlflow' AIRFLOW_CTX_TASK_ID='model_training' AIRFLOW_CTX_EXECUTION_DATE='2024-02-21T10:15:00.704998+00:00' AIRFLOW_CTX_TRY_NUMBER='1' AIRFLOW_CTX_DAG_RUN_ID='manual__2024-02-21T10:15:00.704998+00:00'
[2024-02-21T10:15:24.086+0000] {logging_mixin.py:188} INFO - data imported from s3
[2024-02-21T10:15:24.089+0000] {logging_mixin.py:188} WARNING - usage: *** [-h] [--alpha ALPHA] [--l1_ratio L1_RATIO]
[2024-02-21T10:15:24.090+0000] {logging_mixin.py:188} WARNING - ***: error: unrecognized arguments: scheduler
[2024-02-21T10:15:24.107+0000] {local_task_job_runner.py:234} INFO - Task exited with return code 2
[2024-02-21T10:15:24.132+0000] {taskinstance.py:3280} INFO - 0 downstream tasks scheduled from follow-on schedule check
