[2024-02-21T14:46:57.547+0000] {taskinstance.py:1956} INFO - Dependencies all met for dep_context=non-requeueable deps ti=<TaskInstance: airflow-s3-mlflow.model_prediction manual__2024-02-21T14:46:28.137111+00:00 [queued]>
[2024-02-21T14:46:57.557+0000] {taskinstance.py:1956} INFO - Dependencies all met for dep_context=requeueable deps ti=<TaskInstance: airflow-s3-mlflow.model_prediction manual__2024-02-21T14:46:28.137111+00:00 [queued]>
[2024-02-21T14:46:57.558+0000] {taskinstance.py:2170} INFO - Starting attempt 1 of 1
[2024-02-21T14:46:57.571+0000] {taskinstance.py:2191} INFO - Executing <Task(PythonOperator): model_prediction> on 2024-02-21 14:46:28.137111+00:00
[2024-02-21T14:46:57.579+0000] {standard_task_runner.py:60} INFO - Started process 19475 to run task
[2024-02-21T14:46:57.582+0000] {standard_task_runner.py:87} INFO - Running: ['***', 'tasks', 'run', '***-s3-mlflow', 'model_prediction', 'manual__2024-02-21T14:46:28.137111+00:00', '--job-id', '242', '--raw', '--subdir', 'DAGS_FOLDER/***-aws-mlflow.py', '--cfg-path', '/tmp/tmp7ddw3z5p']
[2024-02-21T14:46:57.584+0000] {standard_task_runner.py:88} INFO - Job 242: Subtask model_prediction
[2024-02-21T14:46:57.601+0000] {logging_mixin.py:188} WARNING - /home/***/.local/lib/python3.8/site-packages/***/settings.py:194 DeprecationWarning: The sql_alchemy_conn option in [core] has been moved to the sql_alchemy_conn option in [database] - the old setting has been used, but please update your config.
[2024-02-21T14:46:57.631+0000] {task_command.py:423} INFO - Running <TaskInstance: airflow-s3-mlflow.model_prediction manual__2024-02-21T14:46:28.137111+00:00 [running]> on host b14d6cdb7c29
[2024-02-21T14:46:57.703+0000] {taskinstance.py:2480} INFO - Exporting env vars: AIRFLOW_CTX_DAG_OWNER='***' AIRFLOW_CTX_DAG_ID='***-s3-mlflow' AIRFLOW_CTX_TASK_ID='model_prediction' AIRFLOW_CTX_EXECUTION_DATE='2024-02-21T14:46:28.137111+00:00' AIRFLOW_CTX_TRY_NUMBER='1' AIRFLOW_CTX_DAG_RUN_ID='manual__2024-02-21T14:46:28.137111+00:00'
[2024-02-21T14:46:57.733+0000] {taskinstance.py:2698} ERROR - Task failed with exception
Traceback (most recent call last):
  File "/home/airflow/.local/lib/python3.8/site-packages/airflow/models/taskinstance.py", line 433, in _execute_task
    result = execute_callable(context=context, **execute_callable_kwargs)
  File "/home/airflow/.local/lib/python3.8/site-packages/airflow/operators/python.py", line 199, in execute
    return_value = self.execute_callable()
  File "/home/airflow/.local/lib/python3.8/site-packages/airflow/operators/python.py", line 216, in execute_callable
    return self.python_callable(*self.op_args, **self.op_kwargs)
  File "/opt/airflow/src/Modeltrainig/prediction.py", line 13, in predict
    prediction = model.predict(test_x,test_y)
TypeError: predict() takes 2 positional arguments but 3 were given
[2024-02-21T14:46:57.750+0000] {taskinstance.py:1138} INFO - Marking task as FAILED. dag_id=***-s3-mlflow, task_id=model_prediction, execution_date=20240221T144628, start_date=20240221T144657, end_date=20240221T144657
[2024-02-21T14:46:57.761+0000] {standard_task_runner.py:107} ERROR - Failed to execute job 242 for task model_prediction (predict() takes 2 positional arguments but 3 were given; 19475)
[2024-02-21T14:46:57.796+0000] {local_task_job_runner.py:234} INFO - Task exited with return code 1
[2024-02-21T14:46:57.823+0000] {taskinstance.py:3280} INFO - 0 downstream tasks scheduled from follow-on schedule check
